<?xml version="1.0" ?>




<robot name="kuka_iiwa">


    <material name="DarpaGrey">
        <color rgba="$(arg material_color)" />
    </material>
        <link name= "world" />
      

       <link name="base_link">
        <inertial>
            <origin xyz="0 0 0.14" rpy="0 -0 0" />
            <mass value="4" />
            <inertia ixx="0.4" iyy="0.4" izz="0.4" ixy="0" ixz="0" iyz="0" />
        </inertial>
        <visual>
                  <material name="DarpaGrey" />

            <origin xyz="0 0 0" rpy="0 -0 0" />
            <geometry>
                <mesh filename= "package://iiwa_robot_model/meshes/base.stl" scale="1 1 1" />
            </geometry>
        </visual>
    
    </link>

      <joint name="world" type="fixed">
        <parent link="world" />
        <child link="base_link" />
        <origin xyz="0.000000 0.000000 0" rpy="0 0 0" />
        <axis xyz="0 0 1" />
        
    </joint>
    <link name="link0">
        <inertial>
            <origin xyz="0 0 0.14" rpy="0 -0 0" />
            <mass value="4" />
            <inertia ixx="0.4" iyy="0.4" izz="0.4" ixy="0" ixz="0" iyz="0" />
        </inertial>
        <visual>
                  <material name="DarpaGrey" />

            <origin xyz="0 0 0" rpy="0 -0 0" />
            <geometry>
                <mesh filename= "package://iiwa_robot_model/meshes/link0.stl" scale="1 1 1" />
            </geometry>
        </visual>
        <!-- <collision>
            <origin xyz="0 0 0" rpy="0 -0 0" />
            <geometry>
                <mesh filename= "package://kuka_iiwa_graphics/link0.stl" scale="1 1 1" />
            </geometry>
        </collision> -->
    </link>
    <link name="link1">
        <inertial>
            <origin xyz="0 0 0.14" rpy="0 -0 0" />
            <mass value="4" />
            <inertia ixx="0.4" iyy="0.4" izz="0.4" ixy="0" ixz="0" iyz="0" />
        </inertial>
        <visual>
          <material name="DarpaGrey" />

            <origin xyz="0 0 0" rpy="0 -0 0" />
            <geometry>
                <mesh filename= "package://iiwa_robot_model/meshes/link1.stl" scale="1 1 1" />
            </geometry>
        </visual>
        <!-- <collision>
            <origin xyz="0 0 0" rpy="0 -0 0" />
            <geometry>
                <mesh filename= "package://kuka_iiwa_graphics/link1.stl" scale="1 1 1" />
            </geometry>
        </collision> -->
    </link>
    <link name="link2">
        <inertial>
            <origin xyz="0 0 0.14" rpy="0 -0 0" />
            <mass value="4" />
            <inertia ixx="0.4" iyy="0.4" izz="0.4" ixy="0" ixz="0" iyz="0" />
        </inertial>
        <visual>
            <material name="DarpaGrey" />
            <origin xyz="0 0 0" rpy="0 -0 0" />
            <geometry>
                <mesh filename= "package://iiwa_robot_model/meshes/link2.stl" scale="1 1 1" />
            </geometry>
        </visual>
        <!-- <collision>
            <origin xyz="0 0 0" rpy="0 -0 0" />
            <geometry>
                <mesh filename= "package://kuka_iiwa_graphics/link2.stl" scale="1 1 1" />
            </geometry>
        </collision> -->
    </link>
    <link name="link3">
        <inertial>
            <origin xyz="0 0 0.14" rpy="0 0 0" />
            <mass value="4" />
            <inertia ixx="0.4" iyy="0.4" izz="0.4" ixy="0" ixz="0" iyz="0" />
        </inertial>
        <visual>
            <material name="DarpaGrey" />
            <origin xyz="0 0 0" rpy="0 0 3.1415926535897" />
            <geometry>
                <mesh filename= "package://iiwa_robot_model/meshes/link3.stl" scale="1 1 1" />
            </geometry>
        </visual>
        <!-- <collision>
            <origin xyz="0 0 0" rpy="0 -0 0" />
            <geometry>
                <mesh filename= "package://kuka_iiwa_graphics/link3.stl" scale="1 1 1" />
            </geometry>
        </collision> -->
    </link>
    <link name="link4">
        <inertial>
            <origin xyz="0 0 0.14" rpy="0 0 0" />
            <mass value="3" />
            <inertia ixx="0.3" iyy="0.3" izz="0.3" ixy="0" ixz="0" iyz="0" />
        </inertial>
        <visual>
            <material name="DarpaGrey" />
            <origin xyz="0 0 0" rpy="0 0 0" />
            <geometry>
                <mesh filename= "package://iiwa_robot_model/meshes/link4.stl" scale="1 1 1" />
            </geometry>
        </visual>
        <!-- <collision>
            <origin xyz="0 0 0" rpy="0 -0 0" />
            <geometry>
                <mesh filename= "package://kuka_iiwa_graphics/link4.stl" scale="1 1 1" />
            </geometry>
        </collision> -->
    </link>
    <link name="link5">
        <inertial>
            <origin xyz="0 0 0.14" rpy="0 0 0" />
            <mass value="2" />
            <inertia ixx="0.2" iyy="0.2" izz="0.2" ixy="0" ixz="0" iyz="0" />
        </inertial>
        <visual>
            <material name="DarpaGrey" />
            <origin xyz="0 -0.06 0" rpy="0 0 0" />
            <geometry>
                <mesh filename= "package://iiwa_robot_model/meshes/link5.stl" scale="1 1 1" />
            </geometry>
        </visual>
        <!-- <collision>
            <origin xyz="0 -0.06 0" rpy="0 -0 0" />
            <geometry>
                <mesh filename= "package://kuka_iiwa_graphics/link5.stl" scale="1 1 1" />
            </geometry>
        </collision> -->
    </link>
    <link name="link6">
        <inertial>
            <origin xyz="0 0 0.03" rpy="0 0 0" />
            <mass value="1" />
            <inertia ixx="0.1" iyy="0.1" izz="0.1" ixy="0" ixz="0" iyz="0" />
        </inertial>
        <visual>
            <material name="DarpaGrey" />
            <origin xyz="0 0 0" rpy="0 0 0" />
            <geometry>
                <mesh filename= "package://iiwa_robot_model/meshes/link6.stl" scale="1 1 1" />
            </geometry>
        </visual>
    <!--     <collision>
            <origin xyz="0 0 0" rpy="0 0 0" />
            <geometry>
                <mesh filename= "package://iiwa_robot_model/meshes/link6.stl" scale="1 1 1" />
            </geometry>
        </collision> -->

        <!-->
              <visual>
            <origin xyz="0.1 0.0 0.06" rpy="0 -0 0.0" />
            <geometry>
                <box size="0.1 0.005 0.02" />
            </geometry>
            <material name="link6-2">
                <color rgba="0.2 0.9 0.1 1.0" />
            </material>
        </visual>
    -->
    </link>

    <link name="Item1">
 +        
 +        <!--
 +        <contact>
 +          <lateral_friction value="0.1"/>
 +          <rolling_friction value="0.0"/>
 +        </contact> -->
 +        <inertial>
 +            <mass value="0.25"/>
 +           <origin rpy="0 0 0" xyz="0 -0.000000 0.0"/>
            <inertia ixx="0.1" iyy="0.1" izz="0.1" ixy="0" ixz="0" iyz="0" />
 +        </inertial>
 +        <visual>
 +          <origin rpy="0 0 0" xyz="0 0 0"/>
 +          <geometry>
 +            <mesh filename="package://iiwa_robot_model/meshes/multicolorpeg.obj" scale="1 1 1 "/> 
 <!-- +          <mesh filename="can/can.obj" scale="1 1 1 "/>  --> -->
 +          
            </geometry>
 +           <material name="green">
 +            <color rgba="0 0.45 0 1"/>
 +          </material>
 +        </visual>
<!-- 
        <collision>
          <origin rpy="0 0 0" xyz="0 0 0"/>
          <geometry>
                <mesh filename="insertion/1hole_4mm_t/1hole4mm-sq_peg_5_5_10-1.obj" scale="1 1 1 "/>
          </geometry>
        </collision>  -->
        

      </link>
   


<joint name="CAMERA_JOINT" type="fixed">
    <parent link="base_link"/>
    <child link="camera_frame"/>
    <!-- <origin rpy="0.7752 0.7852 -0.0142" xyz=".93 -.55 .76"/> -->
    <origin rpy="1.57 0 3.14" xyz="0 -1.1 0.8"/>

  </joint>
  <link name="camera_frame">
    <inertial>
      <origin rpy="0 0 0" xyz="0 0 0"/>
      <mass value="1.0"/>
      <inertia ixx="0.01" ixy="0" ixz="0" iyy="0.01" iyz="0" izz="0.01"/>
    </inertial>

  </link>

    



    <joint name="joint0" type="revolute">
        <parent link="base_link" />
        <child link="link0" />
        <origin xyz="0.000000 0.000000 0.155767" rpy="0.000000 0.000000 0.000000" />
        <axis xyz="0 0 1" />
        <limit lower="-2.967" upper="2.967" effort="176" velocity="1.7104" />
    </joint>
    <joint name="joint1" type="revolute">
        <parent link="link0" />
        <child link="link1" />
        <origin xyz="0.000000 0.000000 0.182500" rpy="0.000000 0.000000 0.000000" />
        <axis xyz="0 1 0" />
        <limit lower="-2.0944" upper="2.0944" effort="176" velocity="1.7104" />
    </joint>
    <joint name="joint2" type="revolute">
        <parent link="link1" />
        <child link="link2" />
        <origin xyz="0.000000 0.000000 0.185000" rpy="0.000000 0.000000 0.000000" />
        <axis xyz="0 0 1" />
        <limit lower="-2.967" upper="2.967" effort="110" velocity="1.7453" />
    </joint>
    <joint name="joint3" type="revolute">
        <parent link="link2" />
        <child link="link3" />
        <origin xyz="0.000000 0.000000 0.217000" rpy="0.000000 0.000000 3.1415926535897" />
        <axis xyz="0 1 0" />
        <limit lower="-2.0944" upper="2.0944" effort="110" velocity="2.2689" />
    </joint>
    <joint name="joint4" type="revolute">
        <parent link="link3" />
        <child link="link4" />
        <origin xyz="0.000000 0.000000 0.186000" rpy="0.000000 0.000000 -3.1415926535897" />
        <axis xyz="0 0 1" />
        <limit lower="-2.967" upper="2.967" effort="110" velocity="2.4434" />
    </joint>
    <joint name="joint5" type="revolute">
        <parent link="link4" />
        <child link="link5" />
        <origin xyz="0.000000 0.000000 0.217003" rpy="0.000000 0.000000 0.000000" />
        <axis xyz="0 1 0" />
        <limit lower="-2.0944" upper="2.0944" effort="40" velocity="3.1416" />
    </joint>
    <joint name="joint6" type="revolute">
        <parent link="link5" />
        <child link="link6" />
        <origin xyz="0.000000 0.000000 0.081000" rpy="0.000000 0.000000 0.000000" />
        <axis xyz="0 0 1" />
        <limit lower="-3.0543" upper="3.0543" effort="40" velocity="3.1416" />
    </joint>


    <joint name="Item1" type="fixed">
        <parent link="link6" />

        <child link="Item1" />
        <origin xyz="0 0 0.03000" rpy="0 0 0" />
        <axis xyz="0 0 1" />
        
    </joint>


</robot>
